<?xml version="1.0" encoding="utf-8"?>
<!-- This URDF was automatically created by SolidWorks to URDF Exporter! Originally created by Stephen Brawner (brawner@gmail.com) 
     Commit Version: 1.6.0-4-g7f85cfe  Build Version: 1.6.7995.38578
     For more information, please see http://wiki.ros.org/sw_urdf_exporter -->
<robot
  name="4-w robot">
  <link
    name="base_link">
    <inertial>
      <origin
        xyz="0.32815 0.63195 0.72248"
        rpy="0 0 0" />
      <mass
        value="74.58" />
      <inertia
        ixx="5.9363"
        ixy="-1.0346E-14"
        ixz="4.269E-16"
        iyy="7.3965"
        iyz="9.6698E-17"
        izz="1.7491" />
    </inertial>
    <visual>
      <origin
        xyz="0 0 0"
        rpy="0 0 0" />
      <geometry>
        <mesh
          filename="package://4-w robot/meshes/base_link.STL" />
      </geometry>
      <material
        name="">
        <color
          rgba="0.79216 0.81961 0.93333 1" />
      </material>
    </visual>
    <collision>
      <origin
        xyz="0 0 0"
        rpy="0 0 0" />
      <geometry>
        <mesh
          filename="package://4-w robot/meshes/base_link.STL" />
      </geometry>
    </collision>
  </link>
  <link
    name="frontrightwheellink">
    <inertial>
      <origin
        xyz="-0.058668 0.0064681 0"
        rpy="0 0 0" />
      <mass
        value="0.056363" />
      <inertia
        ixx="1.2321E-05"
        ixy="-2.1388E-05"
        ixz="3.5958E-20"
        iyy="0.00014386"
        iyz="-1.2705E-20"
        izz="0.00015362" />
    </inertial>
    <visual>
      <origin
        xyz="0 0 0"
        rpy="0 0 0" />
      <geometry>
        <mesh
          filename="package://4-w robot/meshes/frontrightwheellink.STL" />
      </geometry>
      <material
        name="">
        <color
          rgba="0.79216 0.81961 0.93333 1" />
      </material>
    </visual>
    <collision>
      <origin
        xyz="0 0 0"
        rpy="0 0 0" />
      <geometry>
        <mesh
          filename="package://4-w robot/meshes/frontrightwheellink.STL" />
      </geometry>
    </collision>
  </link>
  <joint
    name="frontrightwheellinkjoint"
    type="revolute">
    <origin
      xyz="0.099545 -0.97648 0.40333"
      rpy="1.6082 1.5708 0" />
    <parent
      link="base_link" />
    <child
      link="frontrightwheellink" />
    <axis
      xyz="0 0 0" />
    <limit
      lower="0"
      upper="0"
      effort="0"
      velocity="0" />
  </joint>
  <link
    name="frontrightwheel">
    <inertial>
      <origin
        xyz="-1.1102E-16 0.0408 -1.1102E-16"
        rpy="0 0 0" />
      <mass
        value="2.4494" />
      <inertia
        ixx="0.0075617"
        ixy="-7.5783E-18"
        ixz="1.6941E-21"
        iyy="0.012753"
        iyz="-1.4339E-17"
        izz="0.0075617" />
    </inertial>
    <visual>
      <origin
        xyz="0 0 0"
        rpy="0 0 0" />
      <geometry>
        <mesh
          filename="package://4-w robot/meshes/frontrightwheel.STL" />
      </geometry>
      <material
        name="">
        <color
          rgba="0.79216 0.81961 0.93333 1" />
      </material>
    </visual>
    <collision>
      <origin
        xyz="0 0 0"
        rpy="0 0 0" />
      <geometry>
        <mesh
          filename="package://4-w robot/meshes/frontrightwheel.STL" />
      </geometry>
    </collision>
  </link>
  <joint
    name="frontrightwheeljoint"
    type="fixed">
    <origin
      xyz="0 0.01 0"
      rpy="3.1416 0.0027121 3.1416" />
    <parent
      link="frontrightwheellink" />
    <child
      link="frontrightwheel" />
    <axis
      xyz="0 0 0" />
  </joint>
  <link
    name="frontleftwheellink">
    <inertial>
      <origin
        xyz="-0.058668365874023 0.00646808125522658 0"
        rpy="0 0 0" />
      <mass
        value="0.056363037029715" />
      <inertia
        ixx="1.23212695505758E-05"
        ixy="-2.13878982488817E-05"
        ixz="-7.23607224845394E-20"
        iyy="0.000143856643975693"
        iyz="-6.59032849782056E-21"
        izz="0.00015362112764556" />
    </inertial>
    <visual>
      <origin
        xyz="0 0 0"
        rpy="0 0 0" />
      <geometry>
        <mesh
          filename="package://4-w robot/meshes/frontleftwheellink.STL" />
      </geometry>
      <material
        name="">
        <color
          rgba="0.792156862745098 0.819607843137255 0.933333333333333 1" />
      </material>
    </visual>
    <collision>
      <origin
        xyz="0 0 0"
        rpy="0 0 0" />
      <geometry>
        <mesh
          filename="package://4-w robot/meshes/frontleftwheellink.STL" />
      </geometry>
    </collision>
  </link>
  <joint
    name="frontleftwheellinkjoint"
    type="fixed">
    <origin
      xyz="0.55675 -0.97648 0.40333"
      rpy="1.5708 1.5708 0" />
    <parent
      link="base_link" />
    <child
      link="frontleftwheellink" />
    <axis
      xyz="0 0 0" />
  </joint>
  <link
    name="frontleftwheel">
    <inertial>
      <origin
        xyz="-5.5511E-17 0.0381 -2.2204E-16"
        rpy="0 0 0" />
      <mass
        value="2.4494" />
      <inertia
        ixx="0.0075617"
        ixy="-7.0137E-18"
        ixz="4.7432E-33"
        iyy="0.012753"
        iyz="-3.6826E-18"
        izz="0.0075617" />
    </inertial>
    <visual>
      <origin
        xyz="0 0 0"
        rpy="0 0 0" />
      <geometry>
        <mesh
          filename="package://4-w robot/meshes/frontleftwheel.STL" />
      </geometry>
      <material
        name="">
        <color
          rgba="0.79216 0.81961 0.93333 1" />
      </material>
    </visual>
    <collision>
      <origin
        xyz="0 0 0"
        rpy="0 0 0" />
      <geometry>
        <mesh
          filename="package://4-w robot/meshes/frontleftwheel.STL" />
      </geometry>
    </collision>
  </link>
  <joint
    name="frontleftwheeljoint"
    type="continuous">
    <origin
      xyz="0 0.0889 0"
      rpy="0 0 3.1416" />
    <parent
      link="frontleftwheellink" />
    <child
      link="frontleftwheel" />
    <axis
      xyz="0 0 0" />
  </joint>
  <link
    name="backrightwheel">
    <inertial>
      <origin
        xyz="-3.05311331771918E-16 0.038100000000002 -2.22044604925031E-16"
        rpy="0 0 0" />
      <mass
        value="2.44939228473986" />
      <inertia
        ixx="0.00756174281198395"
        ixy="-5.7592835610494E-18"
        ixz="-2.16840434497101E-19"
        iyy="0.0127531107343337"
        iyz="4.41673265115696E-18"
        izz="0.00756174281198395" />
    </inertial>
    <visual>
      <origin
        xyz="0 0 0"
        rpy="0 0 0" />
      <geometry>
        <mesh
          filename="package://4-w robot/meshes/backrightwheel.STL" />
      </geometry>
      <material
        name="">
        <color
          rgba="0.792156862745098 0.819607843137255 0.933333333333333 1" />
      </material>
    </visual>
    <collision>
      <origin
        xyz="0 0 0"
        rpy="0 0 0" />
      <geometry>
        <mesh
          filename="package://4-w robot/meshes/backrightwheel.STL" />
      </geometry>
    </collision>
  </link>
  <joint
    name="backrightwheeljoint"
    type="continuous">
    <origin
      xyz="0.010645 -0.46848 0.39063"
      rpy="0 1.1039 -1.5708" />
    <parent
      link="base_link" />
    <child
      link="backrightwheel" />
    <axis
      xyz="0 1 0" />
  </joint>
  <link
    name="backleftwheel">
    <inertial>
      <origin
        xyz="0 0 0"
        rpy="0 0 0" />
      <mass
        value="0" />
      <inertia
        ixx="0"
        ixy="0"
        ixz="0"
        iyy="0"
        iyz="0"
        izz="0" />
    </inertial>
    <visual>
      <origin
        xyz="0 0 0"
        rpy="0 0 0" />
      <geometry>
        <mesh
          filename="package://4-w robot/meshes/backleftwheel.STL" />
      </geometry>
      <material
        name="">
        <color
          rgba="1 1 1 1" />
      </material>
    </visual>
    <collision>
      <origin
        xyz="0 0 0"
        rpy="0 0 0" />
      <geometry>
        <mesh
          filename="package://4-w robot/meshes/backleftwheel.STL" />
      </geometry>
    </collision>
  </link>
  <joint
    name="backleftwheeljoint"
    type="continuous">
    <origin
      xyz="0.569445167208001 -0.468481615855647 0.390627691768205"
      rpy="-3.14159265358979 -0.301241685280042 -1.5707963267949" />
    <parent
      link="base_link" />
    <child
      link="backleftwheel" />
    <axis
      xyz="0 1 0" />
  </joint>
</robot>