<?xml version="1.0" encoding="utf-8"?>
<!-- This URDF was automatically created by SolidWorks to URDF Exporter! Originally created by Stephen Brawner (brawner@gmail.com) 
     Commit Version: 1.6.0-4-g7f85cfe  Build Version: 1.6.7995.38578
     For more information, please see http://wiki.ros.org/sw_urdf_exporter -->
<robot
  name="robot">
  <link
    name="chassis_link">
    <inertial>
      <origin
        xyz="0.328145167208003 0.631963802572858 0.722481615855646"
        rpy="0 0 0" />
      <mass
        value="28.5675482792605" />
      <inertia
        ixx="3.6946914856107"
        ixy="-4.45694687956391E-15"
        ixz="4.35859095088725E-16"
        iyy="4.32558875357129"
        iyz="9.62117326446397E-17"
        izz="0.797738644973051" />
    </inertial>
    <visual>
      <origin
        xyz="0 0 0"
        rpy="0 0 0" />
      <geometry>
        <mesh
          filename="package://robot/meshes/chassis_link.STL" />
      </geometry>
      <material
        name="">
        <color
          rgba="1 1 1 1" />
      </material>
    </visual>
    <collision>
      <origin
        xyz="0 0 0"
        rpy="0 0 0" />
      <geometry>
        <mesh
          filename="package://robot/meshes/chassis_link.STL" />
      </geometry>
    </collision>
  </link>
  <link
    name="front_axle">
    <inertial>
      <origin
        xyz="2.22044604925031E-16 -0.00330067603755158 0"
        rpy="0 0 0" />
      <mass
        value="0.21407335442569" />
      <inertia
        ixx="0.00010694118181495"
        ixy="2.7885324538738E-17"
        ixz="2.84896355681426E-18"
        iyy="0.00412680015957867"
        iyz="-1.91856617812422E-21"
        izz="0.0042131304632487" />
    </inertial>
    <visual>
      <origin
        xyz="0 0 0"
        rpy="0 0 0" />
      <geometry>
        <mesh
          filename="package://robot/meshes/front_axle.STL" />
      </geometry>
      <material
        name="">
        <color
          rgba="1 1 1 0.35" />
      </material>
    </visual>
    <collision>
      <origin
        xyz="0 0 0"
        rpy="0 0 0" />
      <geometry>
        <mesh
          filename="package://robot/meshes/front_axle.STL" />
      </geometry>
    </collision>
  </link>
  <joint
    name="front__axle_joint"
    type="fixed">
    <origin
      xyz="0.32815 -0.97648 0.55573"
      rpy="-1.5708 0 0" />
    <parent
      link="chassis_link" />
    <child
      link="front_axle" />
    <axis
      xyz="0 0 0" />
  </joint>
  <link
    name="front_right_link">
    <inertial>
      <origin
        xyz="-0.058668365874023 0.00646808125522669 -1.11022302462516E-16"
        rpy="0 0 0" />
      <mass
        value="0.0603084496217951" />
      <inertia
        ixx="1.31837584191162E-05"
        ixy="-2.28850511263034E-05"
        ixz="-7.74259730584572E-20"
        iyy="0.000153926609053992"
        iyz="-7.051651492668E-21"
        izz="0.000164374606580749" />
    </inertial>
    <visual>
      <origin
        xyz="0 0 0"
        rpy="0 0 0" />
      <geometry>
        <mesh
          filename="package://robot/meshes/front_right_link.STL" />
      </geometry>
      <material
        name="">
        <color
          rgba="1 1 1 0.35" />
      </material>
    </visual>
    <collision>
      <origin
        xyz="0 0 0"
        rpy="0 0 0" />
      <geometry>
        <mesh
          filename="package://robot/meshes/front_right_link.STL" />
      </geometry>
    </collision>
  </link>
  <joint
    name="front_right_link_joint"
    type="revolute">
    <origin
      xyz="0.2286 0.1524 0"
      rpy="3.1416 0 1.5708" />
    <parent
      link="front_axle" />
    <child
      link="front_right_link" />
    <axis
      xyz="0 0 0" />
    <limit
      lower="-45"
      upper="45"
      effort="0"
      velocity="0" />
  </joint>
  <link
    name="front_right_wheel">
    <inertial>
      <origin
        xyz="-5.55111512312578E-17 0.0381 0"
        rpy="0 0 0" />
      <mass
        value="1.6912872736551" />
      <inertia
        ixx="0.00565471643088111"
        ixy="-5.17192084866667E-18"
        ixz="1.77930499547581E-17"
        iyy="0.00967270651555524"
        iyz="-3.04550745131093E-18"
        izz="0.00565471643088112" />
    </inertial>
    <visual>
      <origin
        xyz="0 0 0"
        rpy="0 0 0" />
      <geometry>
        <mesh
          filename="package://robot/meshes/front_right_wheel.STL" />
      </geometry>
      <material
        name="">
        <color
          rgba="1 1 1 0.35" />
      </material>
    </visual>
    <collision>
      <origin
        xyz="0 0 0"
        rpy="0 0 0" />
      <geometry>
        <mesh
          filename="package://robot/meshes/front_right_wheel.STL" />
      </geometry>
    </collision>
  </link>
  <joint
    name="front_right_wheel_joint"
    type="continuous">
    <origin
      xyz="0 0.0889 0"
      rpy="0 0 3.1416" />
    <parent
      link="front_right_link" />
    <child
      link="front_right_wheel" />
    <axis
      xyz="0 0 0" />
  </joint>
  <link
    name="front_left_link">
    <inertial>
      <origin
        xyz="-0.0586683658740229 0.0064680812552268 1.11022302462516E-16"
        rpy="0 0 0" />
      <mass
        value="0.0603084496217952" />
      <inertia
        ixx="1.3183758419116E-05"
        ixy="-2.2885051126303E-05"
        ixz="3.8532669788813E-20"
        iyy="0.000153926609053992"
        iyz="-1.31290106824417E-20"
        izz="0.000164374606580749" />
    </inertial>
    <visual>
      <origin
        xyz="0 0 0"
        rpy="0 0 0" />
      <geometry>
        <mesh
          filename="package://robot/meshes/front_left_link.STL" />
      </geometry>
      <material
        name="">
        <color
          rgba="1 1 1 0.35" />
      </material>
    </visual>
    <collision>
      <origin
        xyz="0 0 0"
        rpy="0 0 0" />
      <geometry>
        <mesh
          filename="package://robot/meshes/front_left_link.STL" />
      </geometry>
    </collision>
  </link>
  <joint
    name="front_left_link_joint"
    type="revolute">
    <origin
      xyz="-0.2286 0.1524 0"
      rpy="-0.037432 0 1.5708" />
    <parent
      link="front_axle" />
    <child
      link="front_left_link" />
    <axis
      xyz="0 0 0" />
    <limit
      lower="-45"
      upper="45"
      effort="0"
      velocity="0" />
  </joint>
  <link
    name="front_left_wheel">
    <inertial>
      <origin
        xyz="-1.11022302462516E-16 0.0408000000000001 -2.22044604925031E-16"
        rpy="0 0 0" />
      <mass
        value="1.6912872736551" />
      <inertia
        ixx="0.00565471643088111"
        ixy="-5.88433788457562E-18"
        ixz="1.79452400205296E-17"
        iyy="0.00967270651555523"
        iyz="-1.08013641433868E-17"
        izz="0.00565471643088111" />
    </inertial>
    <visual>
      <origin
        xyz="0 0 0"
        rpy="0 0 0" />
      <geometry>
        <mesh
          filename="package://robot/meshes/front_left_wheel.STL" />
      </geometry>
      <material
        name="">
        <color
          rgba="1 1 1 0.35" />
      </material>
    </visual>
    <collision>
      <origin
        xyz="0 0 0"
        rpy="0 0 0" />
      <geometry>
        <mesh
          filename="package://robot/meshes/front_left_wheel.STL" />
      </geometry>
    </collision>
  </link>
  <joint
    name="front_left_wheel_joint"
    type="continuous">
    <origin
      xyz="0 0.01 0"
      rpy="3.1416 0.0027121 3.1416" />
    <parent
      link="front_left_link" />
    <child
      link="front_left_wheel" />
    <axis
      xyz="0 0 0" />
  </joint>
  <link
    name="back_axle">
    <inertial>
      <origin
        xyz="3.33066907387547E-16 0.0355687913493262 5.55111512312578E-17"
        rpy="0 0 0" />
      <mass
        value="0.326434896959164" />
      <inertia
        ixx="0.00128767857807481"
        ixy="6.77092858224095E-17"
        ixz="2.84356702671679E-18"
        iyy="0.0106988048504704"
        iyz="4.40908100010494E-20"
        izz="0.0119612848563425" />
    </inertial>
    <visual>
      <origin
        xyz="0 0 0"
        rpy="0 0 0" />
      <geometry>
        <mesh
          filename="package://robot/meshes/back_axle.STL" />
      </geometry>
      <material
        name="">
        <color
          rgba="1 1 1 1" />
      </material>
    </visual>
    <collision>
      <origin
        xyz="0 0 0"
        rpy="0 0 0" />
      <geometry>
        <mesh
          filename="package://robot/meshes/back_axle.STL" />
      </geometry>
    </collision>
  </link>
  <joint
    name="back_axle_joint"
    type="fixed">
    <origin
      xyz="0.32815 -0.46848 0.55573"
      rpy="-1.5708 0 0" />
    <parent
      link="chassis_link" />
    <child
      link="back_axle" />
    <axis
      xyz="0 0 0" />
  </joint>
  <link
    name="back_left_wheel">
    <inertial>
      <origin
        xyz="1.11022302462516E-16 -0.0381000000000018 -2.22044604925031E-16"
        rpy="0 0 0" />
      <mass
        value="1.6912872736551" />
      <inertia
        ixx="0.0056547164308811"
        ixy="2.71322254921917E-18"
        ixz="1.89735380184963E-17"
        iyy="0.00967270651555522"
        iyz="5.11933311497944E-18"
        izz="0.0056547164308811" />
    </inertial>
    <visual>
      <origin
        xyz="0 0 0"
        rpy="0 0 0" />
      <geometry>
        <mesh
          filename="package://robot/meshes/back_left_wheel.STL" />
      </geometry>
      <material
        name="">
        <color
          rgba="1 1 1 0.35" />
      </material>
    </visual>
    <collision>
      <origin
        xyz="0 0 0"
        rpy="0 0 0" />
      <geometry>
        <mesh
          filename="package://robot/meshes/back_left_wheel.STL" />
      </geometry>
    </collision>
  </link>
  <joint
    name="back_left_wheel_joint"
    type="continuous">
    <origin
      xyz="-0.2413 0.1651 0"
      rpy="0 1.3251 -1.5708" />
    <parent
      link="back_axle" />
    <child
      link="back_left_wheel" />
    <axis
      xyz="0 1 0" />
  </joint>
  <link
    name="back_right_wheel">
    <inertial>
      <origin
        xyz="7.7715611723761E-16 -0.0381000000000019 2.4980018054066E-15"
        rpy="0 0 0" />
      <mass
        value="1.6912872736551" />
      <inertia
        ixx="0.00565471643088111"
        ixy="-3.21237594726728E-18"
        ixz="1.86482773667507E-17"
        iyy="0.00967270651555523"
        iyz="4.19840051387123E-18"
        izz="0.00565471643088111" />
    </inertial>
    <visual>
      <origin
        xyz="0 0 0"
        rpy="0 0 0" />
      <geometry>
        <mesh
          filename="package://robot/meshes/back_right_wheel.STL" />
      </geometry>
      <material
        name="">
        <color
          rgba="1 1 1 0.35" />
      </material>
    </visual>
    <collision>
      <origin
        xyz="0 0 0"
        rpy="0 0 0" />
      <geometry>
        <mesh
          filename="package://robot/meshes/back_right_wheel.STL" />
      </geometry>
    </collision>
  </link>
  <joint
    name="back_right_wheel_link"
    type="continuous">
    <origin
      xyz="0.2413 0.1651 0"
      rpy="3.1416 0.98435 -1.5708" />
    <parent
      link="back_axle" />
    <child
      link="back_right_wheel" />
    <axis
      xyz="0 1 0" />
  </joint>
</robot>