<?xml version="1.0" encoding="utf-8"?>

<robot
  name="urdf_file">
  <link 
    name="dummy_link">
    <pose> "0 0 0 0 0 0"</pose>
  </link>
  <joint 
    name="dummy_joint"
    type="fixed">
    <parent
      link="dummy_link" />
    <child
      link="base_link" />
  </joint>
  <link
    name="base_link">
    <inertial>
      <origin
        xyz="-0.034411373133959 1.11213541780183E-05 0.1016"
        rpy="0 0 0" />
      <mass
        value="32.1636737272779" />
      <inertia
        ixx="0.669581472059351"
        ixy="-0.000157679818259281"
        ixz="-2.3149715739769E-18"
        iyy="2.14759610921641"
        iyz="-1.23494349736151E-18"
        izz="2.78472295600065" />
    </inertial>
    <visual>
      <origin
        xyz="0 0 0"
        rpy="0 0 0" />
      <geometry>
        <mesh
          filename="package://urdf_file/meshes/base_link.STL" />
      </geometry>
      <material
        name="">
        <color
          rgba="0.792156862745098 0.819607843137255 0.933333333333333 1" />
      </material>
    </visual>
    <collision>
      <origin
        xyz="0 0 0"
        rpy="0 0 0" />
      <geometry>
        <mesh
          filename="package://urdf_file/meshes/base_link.STL" />
      </geometry>
    </collision>
  </link>
  <link
    name="rear_left_wheel">
    <inertial>
      <origin
        xyz="-9.32860943899242E-16 5.55111512312578E-17 -0.0428410228185393"
        rpy="0 0 0" />
      <mass
        value="2.48230534847962" />
      <inertia
        ixx="0.00840619794732562"
        ixy="-9.87391873143423E-05"
        ixz="1.40975042537836E-19"
        iyy="0.00782887116866109"
        iyz="6.97040447516966E-19"
        izz="0.0121508892249127" />
    </inertial>
    <visual>
      <origin
        xyz="0 0 0"
        rpy="0 0 0" />
      <geometry>
        <mesh
          filename="package://urdf_file/meshes/rear_left_wheel.STL" />
      </geometry>
      <material
        name="">
        <color
          rgba="0.792156862745098 0.819607843137255 0.933333333333333 1" />
      </material>
    </visual>
    <collision>
      <origin
        xyz="0 0 0"
        rpy="0 0 0" />
      <geometry>
        <mesh
          filename="package://urdf_file/meshes/rear_left_wheel.STL" />
      </geometry>
    </collision>
  </link>
  <joint
    name="rear_left_wheel_joint"
    type="continuous">
    <origin
      xyz="-0.2921 -0.3429 0.1016"
      rpy="1.5707963267949 1.5707963267949 0" />
    <parent
      link="base_link" />
    <child
      link="rear_left_wheel" />
    <axis
      xyz="0 0 1" />
  </joint>
  <link
    name="rear_right_wheel">
    <inertial>
      <origin
        xyz="-1.48075352996099E-16 -1.11022302462516E-16 0.0428410228185393"
        rpy="0 0 0" />
      <mass
        value="2.48230534847962" />
      <inertia
        ixx="0.00791346134628071"
        ixy="0.000226782062151254"
        ixz="-4.79062574941557E-20"
        iyy="0.00832160776970599"
        iyz="6.54441713073281E-20"
        izz="0.0121508892249127" />
    </inertial>
    <visual>
      <origin
        xyz="0 0 0"
        rpy="0 0 0" />
      <geometry>
        <mesh
          filename="package://urdf_file/meshes/rear_right_wheel.STL" />
      </geometry>
      <material
        name="">
        <color
          rgba="0.792156862745098 0.819607843137255 0.933333333333333 1" />
      </material>
    </visual>
    <collision>
      <origin
        xyz="0 0 0"
        rpy="0 0 0" />
      <geometry>
        <mesh
          filename="package://urdf_file/meshes/rear_right_wheel.STL" />
      </geometry>
    </collision>
  </link>
  <joint
    name="rear_right_wheel_joint"
    type="continuous">
    <origin
      xyz="-0.2921 0.3429 0.1016"
      rpy="1.5707963267949 1.5707963267949 0" />
    <parent
      link="base_link" />
    <child
      link="rear_right_wheel" />
    <axis
      xyz="0 0 1" />
  </joint>
  <link
    name="attacher_base_right">
    <inertial>
      <origin
        xyz="0.2159 0.248433232856291 0.101587561017618"
        rpy="0 0 0" />
      <mass
        value="0.355491986660241" />
      <inertia
        ixx="0.000546838034350031"
        ixy="5.75931618268393E-21"
        ixz="1.91735477219604E-20"
        iyy="0.000271823706946171"
        iyz="1.92396147569372E-07"
        izz="0.00052462873390416" />
    </inertial>
    <visual>
      <origin
        xyz="0 0 0"
        rpy="0 0 0" />
      <geometry>
        <mesh
          filename="package://urdf_file/meshes/attacher_base_right.STL" />
      </geometry>
      <material
        name="">
        <color
          rgba="0.792156862745098 0.819607843137255 0.933333333333333 1" />
      </material>
    </visual>
    <collision>
      <origin
        xyz="0 0 0"
        rpy="0 0 0" />
      <geometry>
        <mesh
          filename="package://urdf_file/meshes/attacher_base_right.STL" />
      </geometry>
    </collision>
  </link>
  <joint
    name="attacher_base_right_joint"
    type="fixed">
    <origin
      xyz="0 0 0"
      rpy="0 0 0" />
    <parent
      link="base_link" />
    <child
      link="attacher_base_right" />
    <axis
      xyz="0 0 0" />
  </joint>
  <link
    name="attacher_base_left">
    <inertial>
      <origin
        xyz="0.2159 -0.248433232856291 0.101612438982379"
        rpy="0 0 0" />
      <mass
        value="0.355491986660241" />
      <inertia
        ixx="0.000546838034350031"
        ixy="5.18462978621119E-20"
        ixz="-8.15060644614507E-20"
        iyy="0.000271823706946171"
        iyz="1.9239614756665E-07"
        izz="0.00052462873390416" />
    </inertial>
    <visual>
      <origin
        xyz="0 0 0"
        rpy="0 0 0" />
      <geometry>
        <mesh
          filename="package://urdf_file/meshes/attacher_base_left.STL" />
      </geometry>
      <material
        name="">
        <color
          rgba="0.792156862745098 0.819607843137255 0.933333333333333 1" />
      </material>
    </visual>
    <collision>
      <origin
        xyz="0 0 0"
        rpy="0 0 0" />
      <geometry>
        <mesh
          filename="package://urdf_file/meshes/attacher_base_left.STL" />
      </geometry>
    </collision>
  </link>
  <joint
    name="attacher_base_left_joint"
    type="fixed">
    <origin
      xyz="0 0 0"
      rpy="0 0 0" />
    <parent
      link="base_link" />
    <child
      link="attacher_base_left" />
    <axis
      xyz="0 0 0" />
  </joint>
  <link
    name="rotator_left">
    <inertial>
      <origin
        xyz="-0.0222418476214782 -0.000471333073193719 -0.0380864535979338"
        rpy="0 0 0" />
      <mass
        value="0.055906834517021" />
      <inertia
        ixx="1.34991538160197E-05"
        ixy="-8.1209258830838E-07"
        ixz="-2.91771067384044E-19"
        iyy="5.18039733757289E-05"
        iyz="-4.32992189828792E-20"
        izz="4.18327110367438E-05" />
    </inertial>
    <visual>
      <origin
        xyz="0 0 0"
        rpy="0 0 0" />
      <geometry>
        <mesh
          filename="package://urdf_file/meshes/rotator_left.STL" />
      </geometry>
      <material
        name="">
        <color
          rgba="0.792156862745098 0.819607843137255 0.933333333333333 1" />
      </material>
    </visual>
    <collision>
      <origin
        xyz="0 0 0"
        rpy="0 0 0" />
      <geometry>
        <mesh
          filename="package://urdf_file/meshes/rotator_left.STL" />
      </geometry>
    </collision>
  </link>
  <joint
    name="rotator_left_joint"
    type="revolute">
    <origin
      xyz="0.215900000000431 -0.293613689232152 0.0635000000037737"
      rpy="-3.14159265358979 0 1.5707963267949" />
    <parent
      link="base_link" />
    <child
      link="rotator_left" />
    <axis
      xyz="0 0 -1" />
    <limit 
      lower="-0.785398" upper="0.785398" velocity="10" effort="100"/>
  </joint>
  <link
    name="front_left_wheel">
    <inertial>
      <origin
        xyz="3.11532334082215E-12 -4.12336831345783E-13 -0.0381000000021347"
        rpy="0 0 0" />
      <mass
        value="2.3139609092841" />
      <inertia
        ixx="0.00722158167920024"
        ixy="-0.000300689458011547"
        ixz="2.60030253887965E-19"
        iyy="0.00711839584116015"
        iyz="-4.2889222693301E-19"
        izz="0.0121006649900098" />
    </inertial>
    <visual>
      <origin
        xyz="0 0 0"
        rpy="0 0 0" />
      <geometry>
        <mesh
          filename="package://urdf_file/meshes/front_left_wheel.STL" />
      </geometry>
      <material
        name="">
        <color
          rgba="0.792156862745098 0.819607843137255 0.933333333333333 1" />
      </material>
    </visual>
    <collision>
      <origin
        xyz="0 0 0"
        rpy="0 0 0" />
      <geometry>
        <mesh
          filename="package://urdf_file/meshes/front_left_wheel.STL" />
      </geometry>
    </collision>
  </link>
  <joint
    name="front_left_wheel_joint"
    type="continuous">
    <origin
      xyz="-0.107925769603463 -0.0022870844850319 -0.038081971117887"
      rpy="3.12040455150953 -1.5707963267949 0" />
    <parent
      link="rotator_left" />
    <child
      link="front_left_wheel" />
    <axis
      xyz="0.000136968651189618 0.0190364287336147 0.999818781390237" />
  </joint>
  <link
    name="rotator_right">
    <inertial>
      <origin
        xyz="0.022246569974317 -0.00010984064748315 -0.0381694966563745"
        rpy="0 0 0" />
      <mass
        value="0.0559068345170211" />
      <inertia
        ixx="1.34828791554118E-05"
        ixy="1.89292285700758E-07"
        ixz="4.82462564187826E-21"
        iyy="5.18202480363369E-05"
        iyz="-1.50129622114267E-22"
        izz="4.18327110367438E-05" />
    </inertial>
    <visual>
      <origin
        xyz="0 0 0"
        rpy="0 0 0" />
      <geometry>
        <mesh
          filename="package://urdf_file/meshes/rotator_right.STL" />
      </geometry>
      <material
        name="">
        <color
          rgba="0.792156862745098 0.819607843137255 0.933333333333333 1" />
      </material>
    </visual>
    <collision>
      <origin
        xyz="0 0 0"
        rpy="0 0 0" />
      <geometry>
        <mesh
          filename="package://urdf_file/meshes/rotator_right.STL" />
      </geometry>
    </collision>
  </link>
  <joint
    name="rotator_right_joint"
    type="revolute">
    <origin
      xyz="0.2159 0.293613689229737 0.0635"
      rpy="3.14159265358979 0 1.5707963267949" />
    <parent
      link="base_link" />
    <child
      link="rotator_right" />
    <axis
      xyz="0 0 -1" />
    <limit 
      lower="-0.785398" upper="0.785398" velocity="10" effort="100"/>
  </joint>
  <link
    name="front_right_wheel">
    <inertial>
      <origin
        xyz="-3.15773882736403E-18 0.000188113388470273 0.0380995356054779"
        rpy="0 0 0" />
      <mass
        value="2.3139609092841" />
      <inertia
        ixx="0.00747507232160606"
        ixy="-9.75633746895082E-21"
        ixz="4.65093748723565E-19"
        iyy="0.00686503283357574"
        iyz="2.58505120883704E-05"
        izz="0.0121005373551884" />
    </inertial>
    <visual>
      <origin
        xyz="0 0 0"
        rpy="0 0 0" />
      <geometry>
        <mesh
          filename="package://urdf_file/meshes/front_right_wheel.STL" />
      </geometry>
      <material
        name="">
        <color
          rgba="0.792156862745098 0.819607843137255 0.933333333333333 1" />
      </material>
    </visual>
    <collision>
      <origin
        xyz="0 0 0"
        rpy="0 0 0" />
      <geometry>
        <mesh
          filename="package://urdf_file/meshes/front_right_wheel.STL" />
      </geometry>
    </collision>
  </link>
  <joint
    name="front_right_wheel_joint"
    type="continuous">
    <origin
      xyz="0.111758637776069 -0.000551799272846015 -0.0381924929971992"
      rpy="3.14159265358979 -1.5707963267949 0" />
    <parent
      link="rotator_right" />
    <child
      link="front_right_wheel" />
    <axis
      xyz="0.000136968651188685 -0.0021505215480761 0.999997678245635" />
  </joint>
  
  <transmission name="left_wheel_turn_trans">
  <type>transmission_interface/SimpleTransmission</type>
  <joint name="rotator_left_joint">
    <hardwareInterface>hardware_interface/EffortJointInterface</hardwareInterface>
  </joint>
  <actuator name="rotator_left_joint_motor">
  <mechanicalReduction>1</mechanicalReduction>
    <hardwareInterface>hardware_interface/EffortJointInterface</hardwareInterface>
  </actuator>
  </transmission>

  <transmission name="right_wheel_turn_trans">
  <type>transmission_interface/SimpleTransmission</type>
  <joint name="rotator_right_joint">
      <hardwareInterface>hardware_interface/EffortJointInterface</hardwareInterface>
  </joint>
  <actuator name="rotator_right_joint_motor">
  <mechanicalReduction>1</mechanicalReduction>
    <hardwareInterface>hardware_interface/EffortJointInterface</hardwareInterface>
  </actuator>
  </transmission>

  <transmission name="front_left_wheel_speed_trans">
  <type>transmission_interface/SimpleTransmission</type>
  <joint name="front_left_wheel_joint">
      <hardwareInterface>hardware_interface/VelocityJointInterface</hardwareInterface>
  </joint>
  <actuator name="front_left_wheel_speed_motor">
  <mechanicalReduction>1</mechanicalReduction>
    <hardwareInterface>hardware_interface/VelocityJointInterface</hardwareInterface>
  </actuator>
  </transmission>

  <transmission name="front_right_wheel_speed_trans">
  <type>transmission_interface/SimpleTransmission</type>
  <joint name="front_right_wheel_joint">
    <hardwareInterface>hardware_interface/VelocityJointInterface</hardwareInterface>
  </joint>
  <actuator name="front_right_wheel_speed_motor">
  <mechanicalReduction>1</mechanicalReduction>
    <hardwareInterface>hardware_interface/VelocityJointInterface</hardwareInterface>
  </actuator>
  </transmission>

</robot>
